Workbook

Sheet Vocabulary Lists
A1: Id | B1: StageId | C1: LessonId | D1: Audio ID | E1: Gender | F1: Number | G1: Word | H1: Meaning (English) | I1: Meaning (Italian)
A2: 1 | B2: 1 | C2: 1 | D2: 1-1-1 | E2: Male | F2: Singular | G2: هَٰذَا | H2: This | I2: Questo
A3: 2 | B3: 1 | C3: 1 | D3: 1-1-2 | E3: Male | F3: Singular | G3: ذَٰلِكَ | H3: That | I3: Quello
A4: 3 | B4: 1 | C4: 1 | D4: 1-1-3 | E4: Female | F4: Singular | G4: هَٰذِهِ | H4: This | I4: Questa
A5: 4 | B5: 1 | C5: 1 | D5: 1-1-4 | E5: Female | F5: Singular | G5: تِلۡكَ | H5: That | I5: Quella
A6: 5 | B6: 1 | C6: 1 | D6: 1-1-5 | F6: Plural | G6: هَٰٓؤُلَآء | H6: These | I6: Questi
A7: 6 | B7: 1 | C7: 1 | D7: 1-1-6 | F7: Plural | G7: أُوْلَٰٓئِكَ | H7: Those | I7: Quelli
A8: 7 | B8: 1 | C8: 1 | D8: 1-1-7 | E8: Male | F8: Singular | G8: ٱلَّذِي | H8: who | I8: Il quale / Che
A9: 8 | B9: 1 | C9: 1 | D9: 1-1-8 | E9: Female | F9: Singular | G9: ٱلَّتِي | H9: who | I9: La quale / Che
A10: 9 | B10: 1 | C10: 1 | D10: 1-1-9 | F10: Plural | G10: ٱلَّذِينَ | H10: Those who | I10: Coloro che / I quali
A11: 10 | B11: 1 | C11: 1 | D11: 1-1-10 | F11: Plural | G11: ٱلَّتِي | H11: Those who | I11: Coloro che / Le quali
A12: 11 | B12: 1 | C12: 1 | D12: 1-1-11 | F12: Plural | G12: هَٰذِهِ | H12: These | I12: Questi
A13: 12 | B13: 1 | C13: 1 | D13: 1-1-12 | F13: Plural | G13: تِلۡكَ | H13: Those | I13: Quelli
A14: 13 | B14: 1 | C14: 2 | D14: 1-2-1 | G14: نَعَمۡ | H14: Yes | I14: Sì
A15: 14 | B15: 1 | C15: 2 | D15: 1-2-2 | G15: بَلَي | H15: Yes, indeed | I15: Sì, certo / Bensì
A16: 15 | B16: 1 | C16: 2 | D16: 1-2-3 | G16: كَلَّا | H16: Certainly not | I16: Certo che no / Giammai
A17: 16 | B17: 1 | C17: 2 | D17: 1-2-4 | G17: إِلَّا | H17: Except | I17: Eccetto / Tranne
A18: 17 | B18: 1 | C18: 2 | D18: 1-2-5 | G18: إِنۡ .. إِلَّا | H18: Nothing but | I18: Nient'altro che / Soltanto
A19: 18 | B19: 1 | C19: 2 | D19: 1-2-6 | G19: مَا .. إِلَّا | H19: Nothing but | I19: Nient'altro che / Soltanto
A20: 19 | B20: 1 | C20: 2 | D20: 1-2-7 | G20: أَلَّا | H20: So as not to/ that not | I20: Affinchè non / Per non
A21: 20 | B21: 1 | C21: 2 | D21: 1-2-8 | G21: لَا | H21: Do(es) not | I21: Non
A22: 21 | B22: 1 | C22: 2 | D22: 1-2-9 | G22: مَا | H22: Not (continuous) | I22: Non (continuo)
A23: 22 | B23: 1 | C23: 2 | D23: 1-2-10 | G23: لَنۡ | H23: Will not | I23: Non (futuro)
A24: 23 | B24: 1 | C24: 2 | D24: 1-2-11 | G24: لَمۡ | H24: Did not | I24: Non (passato)
A25: 24 | B25: 1 | C25: 2 | D25: 1-2-12 | E25: Male | F25: Singular | G25: لَيۡسَ | H25: (There is) no | I25: Non è / Non c'è
A26: 25 | B26: 1 | C26: 2 | D26: 1-2-13 | E26: Female | F26: Singular | G26: لَيۡسَت | H26: (There is) no | I26: Non è / Non c'è
A27: 26 | B27: 1 | C27: 2 | D27: 1-2-14 | G27: غَيۡر | H27: Other than | I27: All'infuori di
A28: 27 | B28: 1 | C28: 2 | D28: 1-2-15 | G28: غَيۡر | H28: not | I28: Non
A29: 28 | B29: 1 | C29: 2 | D29: 1-2-16 | G29: مِن دُون | H29: Apart from | I29: A parte / All'infuori di
A30: 29 | B30: 1 | C30: 3 | D30: 1-3-1 | G30: أَ | H30: Yes/ no Questions | I30: Domande Sì / no
A31: 30 | B31: 1 | C31: 3 | D31: 1-3-2 | G31: هَلۡ | H31: Yes/ no Questions | I31: Domande Sì / no
A32: 31 | B32: 1 | C32: 3 | D32: 1-3-3 | G32: مَا | H32: What ...? | I32: Cosa...?
A33: 32 | B33: 1 | C33: 3 | D33: 1-3-4 | G33: مَاذا | H33: What ...? | I33: Che cosa...?
A34: 33 | B34: 1 | C34: 3 | D34: 1-3-5 | G34: لِمَ | H34: Why…? | I34: Perché...?
A35: 34 | B35: 1 | C35: 3 | D35: 1-3-6 | G35: مَنۡ | H35: Who...? | I35: Chi...?
A36: 35 | B36: 1 | C36: 3 | D36: 1-3-7 | G36: مَتَى | H36: When ...? | I36: Quando…?
A37: 36 | B37: 1 | C37: 3 | D37: 1-3-8 | G37: أَيۡنَ | H37: Where...? | I37: Dove…?
A38: 37 | B38: 1 | C38: 3 | D38: 1-3-9 | G38: كَيۡفَ | H38: How...? | I38: Come…?
... A175: 174 | B175: 2 | C175: 2 | D175: 2-2-20 | G175: أَدۡنَى | H175: Nearer/ More likely | I175: Più vicino / Più atto
A176: 175 | B176: 2 | C176: 3 | D176: 2-3-1 | E176: Male | F176: Singular | G176: رَسُول | H176: Messenger | I176: Messaggero
...

Sheet Vocab with Examples
A1: Ayahref | B1: WordID | C1: Word | D1: Meaning & Translation in Italian (Hamza Roberto Piccardo) | E1: Meaning & Translation | F1: Highlight
B2: 1 | C2: هَٰذَا | D2: =VLOOKUP(B2, 'Vocabulary Lists'!A:I, 9, FALSE) -> Questo | E2: This
A3: 2:25 | C3: قَالُواْ هَٰذَا ٱلَّذِي رُزِقۡنَا مِن قَبۡلُۖ | D3: diranno: “(questo) Già ci era stato concesso!” | E3: They will say, “This is what we were provided with before,” | F3: هَٰذَا
A4: 2:26 | C4: مَاذَآ أَرَادَ ٱللَّهُ بِهَٰذَا مَثَلٗاۘ | D4: “Cosa vuol dire Allah con un simile (questo) esempio?” | E4: “What did Allah intend by this example?” | F4: بِهَٰذَا
A5: 30:56 | C5: فَهَٰذَا يَوۡمُ ٱلۡبَعۡثِ | D5: ecco (questo è) il Giorno della Resurrezione | E5: This is the Day of Resurrection | F5: فَهَٰذَا
B6: 2 | C6: ذَٰلِكَ | D6: =VLOOKUP(B6, 'Vocabulary Lists'!A:I, 9, FALSE) -> Quello | E6: That
A7: 2:2 | C7: ذَٰلِكَ ٱلۡكِتَٰبُ لَا رَيۡبَۛ فِيهِۛ | D7: Questo (quello) è il Libro su cui non ci sono dubbi | E7: This (that) is the Book in which there is no doubt | F7: بِذَٰلِكَ
A8: 45:24 | C8: وَمَا لَهُم بِذَٰلِكَ مِنۡ عِلۡمٍۖ إِنۡ هُمۡ إِلَّا يَظُنُّون | D8: Invece (di quello) non possiedono nessuna scienza, non fanno altro che illazioni. | E8: Of that they have no knowledge; they are only assuming. | F8: فَذَٰلِكَ
A9: 74:9 | C9: فَذَٰلِكَ يَوۡمَئِذٖ يَوۡمٌ عَسِيرٌ | D9: quello sarà un Giorno difficile, | E9: That Day will be a difficult day. | F9: فَذَٰلِكَ
B10: 3 | C10: هَٰذِهِ | D10: =VLOOKUP(B10, 'Vocabulary Lists'!A:I, 9, FALSE) -> Questa | E10: This
A11: 7:19 | C11: وَلَا تَقۡرَبَا هَٰذِهِ ٱلشَّجَرَةَ | D11: ma non avvicinatevi a questo albero | E11: but do not approach this tree | F11: هَٰذِهِ
A12: 16:30 | C12: لِّلَّذِينَ أَحۡسَنُواْ فِي هَٰذِهِ ٱلدُّنۡيَا حَسَنَةٞۚ | D12: Coloro che fanno il bene avranno il bene in questa vita | E12: For those who do good in this world, is goodness. | F12: هَٰذِهِ
A13: 26:155 | C13: قَالَ هَٰذِهِۦ نَاقَةٞ لَّهَا شِرۡبٞ | D13: “Questa è una cammella: berrà e voi berrete nei giorni stabiliti." | E13: “This is a she-camel; she has her turn of drinking,” | F13: هَٰذِهِۦ
B14: 4 | C14: تِلۡكَ | D14: =VLOOKUP(B14, 'Vocabulary Lists'!A:I, 9, FALSE) -> Quella | E14: That
A15: 2:134 | C15: تِلۡكَ أُمَّةٞ قَدۡ خَلَتۡۖ | D15: Questa (quella) è gente del passato. | E15: That was a nation that has passed on; | F15: تِلۡكَ
A16: 6:83 | C16: وَتِلۡكَ حُجَّتُنَآ ءَاتَيۡنَٰهَآ إِبۡرَٰهِيمَ عَلَىٰ قَوۡمِهِۦۚ | D16: Questo (quello) è l'argomento che fornimmo ad Abramo contro la sua gente. | E16: That was Our argument which We gave to Abraham against his people. | F16: تِلۡكَ
B17: 5 | C17: هَٰٓؤُلَآء | D17: =VLOOKUP(B17, 'Vocabulary Lists'!A:I, 9, FALSE) -> Questi | E17: These
A18: 4:41 | C18: وَجِئۡنَا بِكَ عَلَىٰ هَٰٓؤُلَآءِ شَهِيدٗا | D18: e ti chiameremo a testimone contro di loro (di questi)? | E18: And We bring you as a witness against these? | F18: هَٰٓؤُلَآءِ
A19: 6:53 | C19: لِّيَقُولُوٓاْ أَهَٰٓؤُلَآءِ مَنَّ ٱللَّهُ عَلَيۡهِم | D19: “Sono questi coloro fra noi che Allah ha favorito?” | E19: “Are these the ones whom Allah has favored from among us?” | F19: أَهَٰٓؤُلَآءِ
B20: 6 | C20: أُوْلَٰٓئِكَ | D20: =VLOOKUP(B20, 'Vocabulary Lists'!A:I, 9, FALSE) -> Quelli | E20: Those
A21: 2:5 | C21: أُوْلَٰٓئِكَ عَلَىٰ هُدٗى مِّن رَّبِّهِمۡۖ وَأُوْلَٰٓئِكَ هُمُ ٱلۡمُفۡلِحُونَ | D21: Quelli seguono la guida del loro Signore; quelli sono coloro che prospereranno. | E21: Those are upon [right] guidance from their Lord, and it is those who are the successful. | F21: فَأُوْلَٰٓئِكَ
A22: 2:160 | C22: فَأُوْلَٰٓئِكَ أَتُوبُ عَلَيۡهِمۡ وَأَنَا ٱلتَّوَّابُ ٱلرَّحِيمُ | D22: da costoro (da quelli) Io accetto il pentimento. Io sono Colui Che accoglie il pentimento, il Misericordioso. | E22: Those—I will accept their repentance. I am the Acceptor of Repentance, the Merciful. | F22: فَأُوْلَٰٓئِكَ
B23: 7 | C23: ٱلَّذِي | D23: =VLOOKUP(B23, 'Vocabulary Lists'!A:I, 9, FALSE) -> Il quale / Che | E23: He who
A24: 2:17 | C24: مَثَلُهُمۡ كَمَثَلِ ٱلَّذِي ٱسۡتَوۡقَدَ نَارٗا | D24: Assomigliano a chi (qualcuno che) accende un fuoco | E24: Their likeness is that of a person who kindled a fire; | F24: ٱلَّذِي
A25: 2:259 | C25: أَوۡ كَٱلَّذِي مَرَّ عَلَىٰ قَرۡيَةٖ | D25: O colui che passando presso una città | E25: Or like him who passed by a town | F25: كَٱلَّذِي
A26: 3:72 | C26: ءَامِنُواْ بِٱلَّذِيٓ أُنزِلَ عَلَى ٱلَّذِينَ ءَامَنُواْ | D26: “All'inizio del giorno credete in quello che è stato fatto scendere su coloro che credono | E26: Believe in that which was revealed to the believers | F26: بِٱلَّذِيٓ
B27: 8 | C27: ٱلَّتِي | D27: =VLOOKUP(B27, 'Vocabulary Lists'!A:I, 9, FALSE) -> La quale / Che | E27: She who
A28: 3:131 | C28: وَٱتَّقُواْ ٱلنَّارَ ٱلَّتِيٓ أُعِدَّتۡ لِلۡكَٰفِرِينَ | D28: E temete il Fuoco che è stato preparato per i miscredenti. | E28: And guard yourselves against the Fire that is prepared for the disbelievers. | F28: ٱلَّتِيٓ
A29: 23:96 | C29: ٱدۡفَعۡ بِٱلَّتِي هِيَ أَحۡسَنُ ٱلسَّيِّئَةَۚ نَحۡنُ أَعۡلَمُ بِمَا يَصِفُونَ | D29: Respingi il male con ciò che è migliore. Ben sappiamo quel che dicono. | E29: Repel evil by what is better. We are aware of what they describe. | F29: بِٱلَّتِي
A30: 16:92 | C30: وَلَا تَكُونُواْ كَٱلَّتِي نَقَضَتۡ غَزۡلَهَا | D30: Non fate come colei che disfaceva il suo filato dopo averlo torto a fatica | E30: And do not be like her who untwisted her spun thread, | F30: كَٱلَّتِي
B31: 9 | C31: ٱلَّذِينَ | D31: =VLOOKUP(B31, 'Vocabulary Lists'!A:I, 9, FALSE) -> Coloro che / I quali | E31: Those who
A32: 1:7 | C32: صِرَٰطَ ٱلَّذِينَ أَنۡعَمۡتَ عَلَيۡهِمۡ | D32: la via di coloro che hai colmato di grazia | E32: The path of those whom You have blessed, | F32: ٱلَّذِينَ
A33: 3:105 | C33: وَلَا تَكُونُواْ كَٱلَّذِينَ تَفَرَّقُواْ | D33: E non siate come coloro che si sono divisi | E33: And do not be like those who became divided | F33: كَٱلَّذِينَ
A34: 6:10 | C34: فَحَاقَ بِٱلَّذِينَ سَخِرُواْ مِنۡهُم | D34: Quello di cui si burlavano, (coloro che si burlavano) oggi li avvolge. | E34: but those who mocked them were enveloped by what they used to ridicule. | F34: بِٱلَّذِينَ
B35: 10 | C35: ٱلَّتِي | D35: =VLOOKUP(B35, 'Vocabulary Lists'!A:I, 9, FALSE) -> Coloro che / Le quali | E35: Those who
A36: 7: 157 | C36: وَيَضَعُ عَنۡهُمۡ إِصۡرَهُمۡ وَٱلۡأَغۡلَٰلَ ٱلَّتِي كَانَتۡ عَلَيۡهِمۡۚ | D36: che li libera del loro fardello e dei legami che li opprimono. | E36: and relieves them of their burden and the shackles which were upon zthem. | F36: ٱلَّتِي
A37: 11: 101 | C37: فَمَآ أَغۡنَتۡ عَنۡهُمۡ ءَالِهَتُهُمُ ٱلَّتِي يَدۡعُونَ مِن دُونِ ٱللَّهِ | D37: Gli dèi che invocavano all'infuori di Allah, non li hanno in nulla protetti | E37: And they were not availed at all by their gods which they invoked other than Allah. | F37: ٱلَّتِي
B38: 11 | C38: هَٰذِهِ | D38: =VLOOKUP(B38, 'Vocabulary Lists'!A:I, 9, FALSE) -> Questi | E38: These
A39: 6: 138 | C39: وَقَالُواْ هَٰذِهِۦٓ أَنۡعَٰمٞ وَحَرۡثٌ حِجۡرٞ لَّا يَطۡعَمُهَآ إِلَّا مَن نَّشَآءُ بِزَعۡمِهِمۡ | D39: E dicono: “Ecco (questi sono) i greggi e le messi consacrate: potranno cibarsene solo quelli che designeremo”. Quali pretese! | E39: «And they say, “These animals and crops are forbidden; no one may eat from them except whom we will,” by their claim. | F39: هَٰذِهِۦٓ
A40: 21: 52 | C40: إِذۡ قَالَ لِأَبِيهِ وَقَوۡمِهِۦ مَا هَٰذِهِ ٱلتَّمَاثِيلُ ٱلَّتِيٓ أَنتُمۡ لَهَا عَٰكِفُونَ | D40: Quando disse a suo padre e alla sua gente: “Cosa sono queste statue in cui credete?”. | E40: «When he said to his father and his people, “What are these statues to which you are devoted?”(52)» | F40: هَٰذِهِ
...

Sheet Stages
A1: 1 | B1: PART I | C1: From 0% to 50%
A2: 2 | B2: PART II | C2: From 50% to 65%
A3: 3 | B3: PART III | C3: From 65% to 85%

Sheet Lessons
A2: 1 | B2: 1 | C2: Demonstrative Pronouns
A3: 2 | B3: 1 | C3: Negations & Exceptions
A4: 3 | B4: 1 | C4: Question Words
A5: 4 | B5: 1 | C5: Prepositions I
A6: 5 | B6: 1 | C6: Prepositions II
A7: 6 | B7: 1 | C7: Connectors
A8: 7 | B8: 1 | C8: Miscellaneous
A9: 8 | B9: 1 | C9: Types of ما
A10: 1 | B10: 2 | C10: Allāh’s names & attributes
A11: 2 | B11: 2 | C11: Attributes/ adjectives
A12: 3 | B12: 2 | C12: Prophets and Messengers
A13: 4 | B13: 2 | C13: Allāh’s signs & blessings
... A40: 19 | B40: 3 | C40: Irregular Verbs 5
